<?xml version="1.0" encoding="UTF-8"?>
<testng-results ignored="0" total="11" passed="8" failed="3" skipped="0">
  <reporter-output>
  </reporter-output>
  <suite started-at="2023-11-10T13:55:41 IST" name="Suite" finished-at="2023-11-10T13:56:02 IST" duration-ms="20873">
    <groups>
    </groups>
    <test started-at="2023-11-10T13:55:41 IST" name="Test" finished-at="2023-11-10T13:56:02 IST" duration-ms="20873">
      <class name="aboutTestngXMl.Demo3">
        <test-method signature="A()[pri:0, instance:aboutTestngXMl.Demo3@4f83df68]" started-at="2023-11-10T13:55:42 IST" name="A" finished-at="2023-11-10T13:55:42 IST" duration-ms="8" status="PASS">
          <reporter-output>
          </reporter-output>
        </test-method> <!-- A -->
        <test-method signature="B()[pri:0, instance:aboutTestngXMl.Demo3@4f83df68]" started-at="2023-11-10T13:55:42 IST" name="B" finished-at="2023-11-10T13:55:42 IST" duration-ms="0" status="PASS">
          <reporter-output>
          </reporter-output>
        </test-method> <!-- B -->
        <test-method signature="C()[pri:0, instance:aboutTestngXMl.Demo3@4f83df68]" started-at="2023-11-10T13:55:42 IST" name="C" finished-at="2023-11-10T13:55:42 IST" duration-ms="1" status="PASS">
          <reporter-output>
          </reporter-output>
        </test-method> <!-- C -->
        <test-method signature="Login(java.lang.String,java.lang.String)[pri:0, instance:aboutTestngXMl.Demo3@4f83df68]" started-at="2023-11-10T13:55:42 IST" name="Login" finished-at="2023-11-10T13:55:50 IST" duration-ms="8600" status="FAIL">
          <params>
            <param index="0">
              <value>
                <![CDATA[student]]>
              </value>
            </param>
            <param index="1">
              <value>
                <![CDATA[Password123]]>
              </value>
            </param>
          </params>
          <exception class="java.lang.AssertionError">
            <message>
              <![CDATA[expected [Successfully] but found [Logged In Successfully]]]>
            </message>
            <full-stacktrace>
              <![CDATA[java.lang.AssertionError: expected [Successfully] but found [Logged In Successfully]
at org.testng.Assert.fail(Assert.java:110)
at org.testng.Assert.failNotEquals(Assert.java:1577)
at org.testng.Assert.assertEqualsImpl(Assert.java:149)
at org.testng.Assert.assertEquals(Assert.java:131)
at org.testng.Assert.assertEquals(Assert.java:655)
at org.testng.Assert.assertEquals(Assert.java:665)
at aboutTestngXMl.Demo3.Login(Demo3.java:30)
at java.base/jdk.internal.reflect.NativeMethodAccessorImpl.invoke0(Native Method)
at java.base/jdk.internal.reflect.NativeMethodAccessorImpl.invoke(NativeMethodAccessorImpl.java:77)
at java.base/jdk.internal.reflect.DelegatingMethodAccessorImpl.invoke(DelegatingMethodAccessorImpl.java:43)
at java.base/java.lang.reflect.Method.invoke(Method.java:568)
at org.testng.internal.invokers.MethodInvocationHelper.invokeMethod(MethodInvocationHelper.java:139)
at org.testng.internal.invokers.TestInvoker.invokeMethod(TestInvoker.java:677)
at org.testng.internal.invokers.TestInvoker.invokeTestMethod(TestInvoker.java:221)
at org.testng.internal.invokers.MethodRunner.runInSequence(MethodRunner.java:50)
at org.testng.internal.invokers.TestInvoker$MethodInvocationAgent.invoke(TestInvoker.java:969)
at org.testng.internal.invokers.TestInvoker.invokeTestMethods(TestInvoker.java:194)
at org.testng.internal.invokers.TestMethodWorker.invokeTestMethods(TestMethodWorker.java:148)
at org.testng.internal.invokers.TestMethodWorker.run(TestMethodWorker.java:128)
at java.base/java.util.ArrayList.forEach(ArrayList.java:1511)
at org.testng.TestRunner.privateRun(TestRunner.java:829)
at org.testng.TestRunner.run(TestRunner.java:602)
at org.testng.SuiteRunner.runTest(SuiteRunner.java:437)
at org.testng.SuiteRunner.runSequentially(SuiteRunner.java:431)
at org.testng.SuiteRunner.privateRun(SuiteRunner.java:391)
at org.testng.SuiteRunner.run(SuiteRunner.java:330)
at org.testng.SuiteRunnerWorker.runSuite(SuiteRunnerWorker.java:52)
at org.testng.SuiteRunnerWorker.run(SuiteRunnerWorker.java:95)
at org.testng.TestNG.runSuitesSequentially(TestNG.java:1256)
at org.testng.TestNG.runSuitesLocally(TestNG.java:1176)
at org.testng.TestNG.runSuites(TestNG.java:1099)
at org.testng.TestNG.run(TestNG.java:1067)
at org.testng.remote.AbstractRemoteTestNG.run(AbstractRemoteTestNG.java:115)
at org.testng.remote.RemoteTestNG.initAndRun(RemoteTestNG.java:251)
at org.testng.remote.RemoteTestNG.main(RemoteTestNG.java:77)
]]>
            </full-stacktrace>
          </exception> <!-- java.lang.AssertionError -->
          <reporter-output>
          </reporter-output>
        </test-method> <!-- Login -->
      </class> <!-- aboutTestngXMl.Demo3 -->
      <class name="aboutTestngXMl.Demo2">
        <test-method signature="D()[pri:0, instance:aboutTestngXMl.Demo2@3349e9bb]" started-at="2023-11-10T13:55:50 IST" name="D" finished-at="2023-11-10T13:55:50 IST" duration-ms="1" status="PASS">
          <reporter-output>
          </reporter-output>
        </test-method> <!-- D -->
        <test-method signature="E()[pri:0, instance:aboutTestngXMl.Demo2@3349e9bb]" started-at="2023-11-10T13:55:50 IST" name="E" finished-at="2023-11-10T13:55:50 IST" duration-ms="1" status="PASS">
          <reporter-output>
          </reporter-output>
        </test-method> <!-- E -->
        <test-method signature="Login(java.lang.String,java.lang.String)[pri:0, instance:aboutTestngXMl.Demo2@3349e9bb]" started-at="2023-11-10T13:55:50 IST" name="Login" finished-at="2023-11-10T13:55:56 IST" duration-ms="6237" status="FAIL">
          <params>
            <param index="0">
              <value>
                <![CDATA[student]]>
              </value>
            </param>
            <param index="1">
              <value>
                <![CDATA[Password123]]>
              </value>
            </param>
          </params>
          <exception class="java.lang.AssertionError">
            <message>
              <![CDATA[expected [Successfully] but found [Logged In Successfully]]]>
            </message>
            <full-stacktrace>
              <![CDATA[java.lang.AssertionError: expected [Successfully] but found [Logged In Successfully]
at org.testng.Assert.fail(Assert.java:110)
at org.testng.Assert.failNotEquals(Assert.java:1577)
at org.testng.Assert.assertEqualsImpl(Assert.java:149)
at org.testng.Assert.assertEquals(Assert.java:131)
at org.testng.Assert.assertEquals(Assert.java:655)
at org.testng.Assert.assertEquals(Assert.java:665)
at aboutTestngXMl.Demo2.Login(Demo2.java:30)
at java.base/jdk.internal.reflect.NativeMethodAccessorImpl.invoke0(Native Method)
at java.base/jdk.internal.reflect.NativeMethodAccessorImpl.invoke(NativeMethodAccessorImpl.java:77)
at java.base/jdk.internal.reflect.DelegatingMethodAccessorImpl.invoke(DelegatingMethodAccessorImpl.java:43)
at java.base/java.lang.reflect.Method.invoke(Method.java:568)
at org.testng.internal.invokers.MethodInvocationHelper.invokeMethod(MethodInvocationHelper.java:139)
at org.testng.internal.invokers.TestInvoker.invokeMethod(TestInvoker.java:677)
at org.testng.internal.invokers.TestInvoker.invokeTestMethod(TestInvoker.java:221)
at org.testng.internal.invokers.MethodRunner.runInSequence(MethodRunner.java:50)
at org.testng.internal.invokers.TestInvoker$MethodInvocationAgent.invoke(TestInvoker.java:969)
at org.testng.internal.invokers.TestInvoker.invokeTestMethods(TestInvoker.java:194)
at org.testng.internal.invokers.TestMethodWorker.invokeTestMethods(TestMethodWorker.java:148)
at org.testng.internal.invokers.TestMethodWorker.run(TestMethodWorker.java:128)
at java.base/java.util.ArrayList.forEach(ArrayList.java:1511)
at org.testng.TestRunner.privateRun(TestRunner.java:829)
at org.testng.TestRunner.run(TestRunner.java:602)
at org.testng.SuiteRunner.runTest(SuiteRunner.java:437)
at org.testng.SuiteRunner.runSequentially(SuiteRunner.java:431)
at org.testng.SuiteRunner.privateRun(SuiteRunner.java:391)
at org.testng.SuiteRunner.run(SuiteRunner.java:330)
at org.testng.SuiteRunnerWorker.runSuite(SuiteRunnerWorker.java:52)
at org.testng.SuiteRunnerWorker.run(SuiteRunnerWorker.java:95)
at org.testng.TestNG.runSuitesSequentially(TestNG.java:1256)
at org.testng.TestNG.runSuitesLocally(TestNG.java:1176)
at org.testng.TestNG.runSuites(TestNG.java:1099)
at org.testng.TestNG.run(TestNG.java:1067)
at org.testng.remote.AbstractRemoteTestNG.run(AbstractRemoteTestNG.java:115)
at org.testng.remote.RemoteTestNG.initAndRun(RemoteTestNG.java:251)
at org.testng.remote.RemoteTestNG.main(RemoteTestNG.java:77)
]]>
            </full-stacktrace>
          </exception> <!-- java.lang.AssertionError -->
          <reporter-output>
          </reporter-output>
        </test-method> <!-- Login -->
      </class> <!-- aboutTestngXMl.Demo2 -->
      <class name="aboutTestngXMl.Demo1">
        <test-method is-config="true" signature="m4()[pri:0, instance:aboutTestngXMl.Demo1@41d477ed]" started-at="2023-11-10T13:55:41 IST" name="m4" finished-at="2023-11-10T13:55:41 IST" duration-ms="10" status="PASS">
          <reporter-output>
          </reporter-output>
        </test-method> <!-- m4 -->
        <test-method is-config="true" signature="m1()[pri:0, instance:aboutTestngXMl.Demo1@41d477ed]" started-at="2023-11-10T13:55:41 IST" name="m1" finished-at="2023-11-10T13:55:41 IST" duration-ms="1" status="PASS">
          <reporter-output>
          </reporter-output>
        </test-method> <!-- m1 -->
        <test-method is-config="true" signature="m2()[pri:0, instance:aboutTestngXMl.Demo1@41d477ed]" started-at="2023-11-10T13:55:56 IST" name="m2" finished-at="2023-11-10T13:55:56 IST" duration-ms="2" status="PASS">
          <reporter-output>
          </reporter-output>
        </test-method> <!-- m2 -->
        <test-method signature="I()[pri:0, instance:aboutTestngXMl.Demo1@41d477ed]" started-at="2023-11-10T13:55:56 IST" name="I" finished-at="2023-11-10T13:55:56 IST" duration-ms="2" status="PASS">
          <reporter-output>
          </reporter-output>
        </test-method> <!-- I -->
        <test-method signature="J()[pri:0, instance:aboutTestngXMl.Demo1@41d477ed]" started-at="2023-11-10T13:55:56 IST" name="J" finished-at="2023-11-10T13:55:56 IST" duration-ms="4" status="PASS">
          <reporter-output>
          </reporter-output>
        </test-method> <!-- J -->
        <test-method signature="Login(java.lang.String,java.lang.String)[pri:0, instance:aboutTestngXMl.Demo1@41d477ed]" started-at="2023-11-10T13:55:56 IST" name="Login" finished-at="2023-11-10T13:56:02 IST" duration-ms="5942" status="FAIL">
          <params>
            <param index="0">
              <value>
                <![CDATA[student]]>
              </value>
            </param>
            <param index="1">
              <value>
                <![CDATA[Password123]]>
              </value>
            </param>
          </params>
          <exception class="java.lang.AssertionError">
            <message>
              <![CDATA[expected [Successfully] but found [Logged In Successfully]]]>
            </message>
            <full-stacktrace>
              <![CDATA[java.lang.AssertionError: expected [Successfully] but found [Logged In Successfully]
at org.testng.Assert.fail(Assert.java:110)
at org.testng.Assert.failNotEquals(Assert.java:1577)
at org.testng.Assert.assertEqualsImpl(Assert.java:149)
at org.testng.Assert.assertEquals(Assert.java:131)
at org.testng.Assert.assertEquals(Assert.java:655)
at org.testng.Assert.assertEquals(Assert.java:665)
at aboutTestngXMl.Demo1.Login(Demo1.java:44)
at java.base/jdk.internal.reflect.NativeMethodAccessorImpl.invoke0(Native Method)
at java.base/jdk.internal.reflect.NativeMethodAccessorImpl.invoke(NativeMethodAccessorImpl.java:77)
at java.base/jdk.internal.reflect.DelegatingMethodAccessorImpl.invoke(DelegatingMethodAccessorImpl.java:43)
at java.base/java.lang.reflect.Method.invoke(Method.java:568)
at org.testng.internal.invokers.MethodInvocationHelper.invokeMethod(MethodInvocationHelper.java:139)
at org.testng.internal.invokers.TestInvoker.invokeMethod(TestInvoker.java:677)
at org.testng.internal.invokers.TestInvoker.invokeTestMethod(TestInvoker.java:221)
at org.testng.internal.invokers.MethodRunner.runInSequence(MethodRunner.java:50)
at org.testng.internal.invokers.TestInvoker$MethodInvocationAgent.invoke(TestInvoker.java:969)
at org.testng.internal.invokers.TestInvoker.invokeTestMethods(TestInvoker.java:194)
at org.testng.internal.invokers.TestMethodWorker.invokeTestMethods(TestMethodWorker.java:148)
at org.testng.internal.invokers.TestMethodWorker.run(TestMethodWorker.java:128)
at java.base/java.util.ArrayList.forEach(ArrayList.java:1511)
at org.testng.TestRunner.privateRun(TestRunner.java:829)
at org.testng.TestRunner.run(TestRunner.java:602)
at org.testng.SuiteRunner.runTest(SuiteRunner.java:437)
at org.testng.SuiteRunner.runSequentially(SuiteRunner.java:431)
at org.testng.SuiteRunner.privateRun(SuiteRunner.java:391)
at org.testng.SuiteRunner.run(SuiteRunner.java:330)
at org.testng.SuiteRunnerWorker.runSuite(SuiteRunnerWorker.java:52)
at org.testng.SuiteRunnerWorker.run(SuiteRunnerWorker.java:95)
at org.testng.TestNG.runSuitesSequentially(TestNG.java:1256)
at org.testng.TestNG.runSuitesLocally(TestNG.java:1176)
at org.testng.TestNG.runSuites(TestNG.java:1099)
at org.testng.TestNG.run(TestNG.java:1067)
at org.testng.remote.AbstractRemoteTestNG.run(AbstractRemoteTestNG.java:115)
at org.testng.remote.RemoteTestNG.initAndRun(RemoteTestNG.java:251)
at org.testng.remote.RemoteTestNG.main(RemoteTestNG.java:77)
]]>
            </full-stacktrace>
          </exception> <!-- java.lang.AssertionError -->
          <reporter-output>
          </reporter-output>
        </test-method> <!-- Login -->
        <test-method signature="H()[pri:0, instance:aboutTestngXMl.Demo1@41d477ed]" started-at="2023-11-10T13:56:02 IST" name="H" finished-at="2023-11-10T13:56:02 IST" depends-on-methods="aboutTestngXMl.Demo1.I" duration-ms="2" status="PASS">
          <reporter-output>
          </reporter-output>
        </test-method> <!-- H -->
      </class> <!-- aboutTestngXMl.Demo1 -->
    </test> <!-- Test -->
  </suite> <!-- Suite -->
</testng-results>
