<?xml version="1.0" encoding="UTF-8"?>
<testng-results ignored="0" total="2" passed="0" failed="1" skipped="1">
  <reporter-output>
  </reporter-output>
  <suite started-at="2023-11-11T14:21:51 IST" name="Suite" finished-at="2023-11-11T14:21:51 IST" duration-ms="81">
    <groups>
    </groups>
    <test started-at="2023-11-11T14:21:51 IST" name="Test" finished-at="2023-11-11T14:21:51 IST" duration-ms="81">
      <class name="aboutTestngXMl.InvoactionCountEx">
        <test-method signature="m1()[pri:0, instance:aboutTestngXMl.InvoactionCountEx@57a3af25]" started-at="2023-11-11T14:21:51 IST" name="m1" finished-at="2023-11-11T14:21:51 IST" duration-ms="25" status="FAIL">
          <exception class="java.lang.AssertionError">
            <message>
              <![CDATA[expected [true] but found [false]]]>
            </message>
            <full-stacktrace>
              <![CDATA[java.lang.AssertionError: expected [true] but found [false]
at org.testng.Assert.fail(Assert.java:110)
at org.testng.Assert.failNotEquals(Assert.java:1577)
at org.testng.Assert.assertTrue(Assert.java:56)
at org.testng.Assert.assertTrue(Assert.java:66)
at aboutTestngXMl.InvoactionCountEx.m1(InvoactionCountEx.java:13)
at java.base/jdk.internal.reflect.NativeMethodAccessorImpl.invoke0(Native Method)
at java.base/jdk.internal.reflect.NativeMethodAccessorImpl.invoke(NativeMethodAccessorImpl.java:77)
at java.base/jdk.internal.reflect.DelegatingMethodAccessorImpl.invoke(DelegatingMethodAccessorImpl.java:43)
at java.base/java.lang.reflect.Method.invoke(Method.java:568)
at org.testng.internal.invokers.MethodInvocationHelper.invokeMethod(MethodInvocationHelper.java:139)
at org.testng.internal.invokers.TestInvoker.invokeMethod(TestInvoker.java:677)
at org.testng.internal.invokers.TestInvoker.invokeTestMethod(TestInvoker.java:221)
at org.testng.internal.invokers.MethodRunner.runInSequence(MethodRunner.java:50)
at org.testng.internal.invokers.TestInvoker$MethodInvocationAgent.invoke(TestInvoker.java:969)
at org.testng.internal.invokers.TestInvoker.invokeTestMethods(TestInvoker.java:194)
at org.testng.internal.invokers.TestMethodWorker.invokeTestMethods(TestMethodWorker.java:148)
at org.testng.internal.invokers.TestMethodWorker.run(TestMethodWorker.java:128)
at java.base/java.util.ArrayList.forEach(ArrayList.java:1511)
at org.testng.TestRunner.privateRun(TestRunner.java:829)
at org.testng.TestRunner.run(TestRunner.java:602)
at org.testng.SuiteRunner.runTest(SuiteRunner.java:437)
at org.testng.SuiteRunner.runSequentially(SuiteRunner.java:431)
at org.testng.SuiteRunner.privateRun(SuiteRunner.java:391)
at org.testng.SuiteRunner.run(SuiteRunner.java:330)
at org.testng.SuiteRunnerWorker.runSuite(SuiteRunnerWorker.java:52)
at org.testng.SuiteRunnerWorker.run(SuiteRunnerWorker.java:95)
at org.testng.TestNG.runSuitesSequentially(TestNG.java:1256)
at org.testng.TestNG.runSuitesLocally(TestNG.java:1176)
at org.testng.TestNG.runSuites(TestNG.java:1099)
at org.testng.TestNG.run(TestNG.java:1067)
at org.testng.remote.AbstractRemoteTestNG.run(AbstractRemoteTestNG.java:115)
at org.testng.remote.RemoteTestNG.initAndRun(RemoteTestNG.java:251)
at org.testng.remote.RemoteTestNG.main(RemoteTestNG.java:77)
]]>
            </full-stacktrace>
          </exception> <!-- java.lang.AssertionError -->
          <reporter-output>
          </reporter-output>
        </test-method> <!-- m1 -->
        <test-method signature="m2()[pri:0, instance:aboutTestngXMl.InvoactionCountEx@57a3af25]" started-at="2023-11-11T14:21:51 IST" name="m2" finished-at="2023-11-11T14:21:51 IST" depends-on-methods="aboutTestngXMl.InvoactionCountEx.m1" duration-ms="1" status="SKIP">
          <exception class="java.lang.Throwable">
            <message>
              <![CDATA[Method aboutTestngXMl.InvoactionCountEx.m2() on instance aboutTestngXMl.InvoactionCountEx@57a3af25 depends on not successfully finished methods 
[aboutTestngXMl.InvoactionCountEx.m1() on instance aboutTestngXMl.InvoactionCountEx@57a3af25]]]>
            </message>
            <full-stacktrace>
              <![CDATA[java.lang.Throwable: Method aboutTestngXMl.InvoactionCountEx.m2() on instance aboutTestngXMl.InvoactionCountEx@57a3af25 depends on not successfully finished methods 
[aboutTestngXMl.InvoactionCountEx.m1() on instance aboutTestngXMl.InvoactionCountEx@57a3af25]
at org.testng.internal.invokers.TestInvoker.invokeTestMethods(TestInvoker.java:150)
at org.testng.internal.invokers.TestMethodWorker.invokeTestMethods(TestMethodWorker.java:148)
at org.testng.internal.invokers.TestMethodWorker.run(TestMethodWorker.java:128)
at java.base/java.util.ArrayList.forEach(ArrayList.java:1511)
at org.testng.TestRunner.privateRun(TestRunner.java:829)
at org.testng.TestRunner.run(TestRunner.java:602)
at org.testng.SuiteRunner.runTest(SuiteRunner.java:437)
at org.testng.SuiteRunner.runSequentially(SuiteRunner.java:431)
at org.testng.SuiteRunner.privateRun(SuiteRunner.java:391)
at org.testng.SuiteRunner.run(SuiteRunner.java:330)
at org.testng.SuiteRunnerWorker.runSuite(SuiteRunnerWorker.java:52)
at org.testng.SuiteRunnerWorker.run(SuiteRunnerWorker.java:95)
at org.testng.TestNG.runSuitesSequentially(TestNG.java:1256)
at org.testng.TestNG.runSuitesLocally(TestNG.java:1176)
at org.testng.TestNG.runSuites(TestNG.java:1099)
at org.testng.TestNG.run(TestNG.java:1067)
at org.testng.remote.AbstractRemoteTestNG.run(AbstractRemoteTestNG.java:115)
at org.testng.remote.RemoteTestNG.initAndRun(RemoteTestNG.java:251)
at org.testng.remote.RemoteTestNG.main(RemoteTestNG.java:77)
]]>
            </full-stacktrace>
          </exception> <!-- java.lang.Throwable -->
          <reporter-output>
          </reporter-output>
        </test-method> <!-- m2 -->
      </class> <!-- aboutTestngXMl.InvoactionCountEx -->
    </test> <!-- Test -->
  </suite> <!-- Suite -->
</testng-results>
